Traceback (most recent call last):
  File "/Users/lmoresi/opt/anaconda3/envs/jupyterbook/lib/python3.7/site-packages/nbclient/client.py", line 609, in _async_poll_for_reply
    msg = await ensure_async(self.kc.shell_channel.get_msg(timeout=new_timeout))
  File "/Users/lmoresi/opt/anaconda3/envs/jupyterbook/lib/python3.7/site-packages/nbclient/util.py", line 85, in ensure_async
    result = await obj
  File "/Users/lmoresi/opt/anaconda3/envs/jupyterbook/lib/python3.7/site-packages/jupyter_client/asynchronous/channels.py", line 48, in get_msg
    raise Empty
_queue.Empty

During handling of the above exception, another exception occurred:

Traceback (most recent call last):
  File "/Users/lmoresi/opt/anaconda3/envs/jupyterbook/lib/python3.7/site-packages/jupyter_cache/executors/utils.py", line 56, in single_nb_execution
    record_timing=False,
  File "/Users/lmoresi/opt/anaconda3/envs/jupyterbook/lib/python3.7/site-packages/nbclient/client.py", line 1087, in execute
    return NotebookClient(nb=nb, resources=resources, km=km, **kwargs).execute()
  File "/Users/lmoresi/opt/anaconda3/envs/jupyterbook/lib/python3.7/site-packages/nbclient/util.py", line 74, in wrapped
    return just_run(coro(*args, **kwargs))
  File "/Users/lmoresi/opt/anaconda3/envs/jupyterbook/lib/python3.7/site-packages/nbclient/util.py", line 53, in just_run
    return loop.run_until_complete(coro)
  File "/Users/lmoresi/opt/anaconda3/envs/jupyterbook/lib/python3.7/asyncio/base_events.py", line 587, in run_until_complete
    return future.result()
  File "/Users/lmoresi/opt/anaconda3/envs/jupyterbook/lib/python3.7/site-packages/nbclient/client.py", line 541, in async_execute
    cell, index, execution_count=self.code_cells_executed + 1
  File "/Users/lmoresi/opt/anaconda3/envs/jupyterbook/lib/python3.7/site-packages/nbclient/client.py", line 816, in async_execute_cell
    exec_reply = await self.task_poll_for_reply
  File "/Users/lmoresi/opt/anaconda3/envs/jupyterbook/lib/python3.7/site-packages/nbclient/client.py", line 633, in _async_poll_for_reply
    await self._async_handle_timeout(timeout, cell)
  File "/Users/lmoresi/opt/anaconda3/envs/jupyterbook/lib/python3.7/site-packages/nbclient/client.py", line 684, in _async_handle_timeout
    "Cell execution timed out", timeout, cell
nbclient.exceptions.CellTimeoutError: A cell timed out while it was being executed, after 30 seconds.
The message was: Cell execution timed out.
Here is a preview of the cell contents:
-------------------
['## Read ETOPO1 data from online service', '#', '# Note the slicing is a mix of the data range and the integer step', '', 'import xarray']
...
["lats = etopo_coarse.coords.get('y')", "vals = etopo_coarse['z']", '', 'x,y = np.meshgrid(lons.data, lats.data)', 'height = 6.370 + 1.0e-6 * vals.data']
-------------------

